# 8장. 예외처리

## 1. 프로그램 오류

프로그램 오류의 3가지 종류

1. **컴파일 에러**: 컴파일 시에 발생하는 에러
2. **런타임 에러**: 실행 시에 발생하는 에러
3. **논리적 에러**: 실행은 되지만, 의도와 다르게 동작하는 것

자바에서는 실행 시(runtime) 발생할 수 있는 프로그램 오류를 “에러”와 “예외”로 구분하는데, “에러”는 `메모리 부족(OutOfMemoryError)`이나 `스택오버플로우(StackOverflowError)`와 같이 심각한 오류이고, “예외”는 발생하더라도 수습될 수 있는 비교적 덜 심각한 것이다. 

예외는 프로그래머가 이에 대한 적절한 코드를 **미리 작성해 놓음으로써 프로그램의 비정상적인 종료를 막을 수 있다.** 

## 2. 예외 클래스의 계층 구조

자바에서는 실행 시 발생할 수 잇는 오류를 “클래스”로 정의하였다. 모든 클래스의 조상은 `Object 클래스`이므로 `Exception`과 `Error` 클래스 역시 Object 클래스의 자손들이다. 

`Exception 클래스`의 자손들에는 `RuntimeException클래스`와 `IOException`, `ClassNotFouneException` 등등이 있는데, 이제부터는 `RuntimeException`클래스와 그 자손 클래스들을 `‘RuntimeException클래스들’,` 나머지 클래스들을 `‘Exception클래스들’` 이라고 부르겠다. 

```
💡 Exception클래스들 - 사용자의 실수와 같은 외적인 요인에 의해 발생하는 에러
   RuntimeException클래스들 - 프로그래머의 실수로 발생하는 에러
```

## 3. 예외 처리하기 - try-catch문

예외 처리란, 프로그램 실행 시 발생할 수 있는 예기치 못한 예외에 대비한 코드를 작성하는 것이며, 발생한 예외를 처리하지 못하면 프로그램은 비정상적으로 종료되고 처리되지 못한 예외는 JVM의 “예외 처리기”가 받아서 예외의 원인을 화면에 출력한다. 

예제 8-3/ExceptionEx3.java
![ExceptionEx3.png](/image/ExceptionEx3.png)

이 메시지를 보면, 0으로 나누려고 했기 때문에 `‘ArithmeticException’`이 발생했고, `ArithmeticException`은 산술 연살 과정에서 오류가 있을 때 발생하는 예외이다. 여기서는 정수를 0으로 나누려 했기 때문에 에러가 발생했다. 

아래는 `try-catch문`을 추가해서 예외가 발생하더라도 프로그램이 비정상적으로 종료되지 않게 수정한 코드이다. 

```java
public class ExceptionEx3 {
    public static void main(String[] args) {
        int number = 100;
        int result = 0;

        for (int i = 0; i < 10; i++) {
            try {
                result = number / (int) (Math.random() * 10);
                System.out.println(result);
            } catch (ArithmeticException e) {
                System.out.println("0");
            }
        }
    }
}
```

⇒ 이렇게 바꾸니까 에러가 발생하더라도 프로그램이 실행 도중에 종료되지 않는다. 

## 4. try-catch문에서의 흐름

- **try블럭 내에서 예외가 발생한 경우**
    1. 발생한 예외와 일치하는 `catch블럭`이 있는지 찾는다.
    2. 일치하는 `catch블럭`을 찾게 되면, 그 `catch블럭` 내의 문장들을 수행하고 전체 `try-catch문`을 빠져나가서 수행을 계속한다. 
    3. 만일 일치하는 `catch블럭`이 없으면, 예외는 처리되지 않는다. 
- **try블럭 내에서 예외가 발생하지 않은 경우**
    1. `catch블럭`을 건너뛰고 전체 `try-catch문`을 빠져나가서 수행을 계속한다. 

`try블럭`에서 예외가 발생하면, 예외가 발생한 위치 이후에 있는 `try블럭`의 문장들은 수행되지 않는다.

```java
try {
	System.out.println(0/0); // 0으로 나눠서 고의로 ArithmeticException 발생시킴
	System.out.println(4);   // 실행되지 않는다!
}
```

## 5. 예외의 발생과 catch블럭

`catch블럭`은 `괄호()`와 `블럭{}`으로 나눠져 있는데, `괄호()`에는 처리하려는 예외와 같은 타입의 **참조 변수를 선언**하고, `블럭{}`에는 예외가 발생했을 때 **실행될 문장들**을 넣는다. 

예외가 발생하면, 발생한 **예외에 해당하는 클래스의 인스턴스가 만들어진다**. 이 인스턴스에는 발생한 예외에 대한 정보가 담겨있으며, `괄호()`안의 참조 변수로 **발생한 예외의 정보를 얻을 수 있다.** 

`try블럭` 내에서 예외가 발생하면, 첫 번째 `catch블럭`부터 차례로 내려가면서 `catch블럭`의 `괄호()`내에 선언된 참조 변수의 타입과 생성된 예외 인스턴스를 `instanceof연산자`로 검사한다. 검사 결과가 `true`인 `catch블럭`을 찾으면 블럭에 있는 문장들을 수행한 후에 `try-catch문`을 빠져나가고 예외는 처리된다. 그러나 검사결과가 `true`인 `catch블럭`이 하나도 없으면 예외는 처리되지 않는다.

**모든 예외 클래스는 Exception의 자손**이므로, `catch블럭`의 `괄호()`에 `Exception`타입의 참조 변수를 선언하면 어떤 종류의 예외가 발생해도 이 `catch블럭`에 의해 처리된다. 

이처럼 `try-catch문`의 마지막에 `Exception`타입의 참조 변수를 선언한 `catch블럭`을 놓으면, 어떤 종류의 예외가 발생해도 이 `catch블럭`에 의해 처리된다. 

예제 8-7/ExceptionEx7.java

```java
public class ExceptionEx7 {
    public static void main(String[] args) {
        System.out.println(1);
        System.out.println(2);
        try {
            System.out.println(3);
            System.out.println(0 / 0);
            System.out.println(4);
        } catch (**ArithmeticException ae**) { // 컴파일 단계에서 타입 결정
            if (**ae instanceof ArithmeticException**) { // 런타임에 객체의 실제 타입 확인
                System.out.println("true");
            }
            System.out.println("ArithmeticException");
        } catch (**Exception e**) { // ArithmeticException을 제외한 모든 에러 처리
            System.out.println("Exception");
        }
        System.out.println(6);
    }
}
```

만약 `ArithmeticException ae` 와 `Exception e` 의 순서를 바꾼다면? 

![ExceptionEx7.png](/image/ExceptionEx7.png)

`ArithmeticException` 에러가 이미 처리 되었다고 자바에서 컴파일 에러를 내뱉는다. 

### printStackTrace()와 getMessage()

`catch블럭`의 `괄호()`에 선언된 참조 변수를 통해서 예외 인스턴스에 접근할 수 있는데, 이 참조 변수는 선언된 `catch블럭` 내에서만 사용 가능하며, 자주 사용되는 메서드는 다음과 같다. 

```
printStackTrace() - 예외 발생 당시의 호출스택(Call Stack)에 있었던 메서드의 정보와 예외 메시지를 화면에 출력한다. 
getMessage()      - 발생한 예외 클래스의 인스턴스에 저장된 메시지를 얻을 수 있다. 
```

### 멀티 catch블럭

여러 `catch블럭`을 `‘|’` 기호를 이용해서, 하나의 `catch블럭`으로 합치는 것

(참고. ‘|’는 논리 연산자가 아니다.)

```java
try {
  ...
} catch (ExceptionA e) {
  e.printStackTrace();
} catch (ExceptionB e2) {
  e2.printStackTrace();
}
```

```java
try {
  ...
} catch (ExceptionA | ExceptionB e) {
  e.printStackTrace();
}
```

주의할 점은 멀티 `catch블럭`의 `‘|’` 기호로 연결된 예외 클래스가 **조상과 자손의 관계**에 있다면 **컴파일 에러**가 발생한다는 것이다. 그런 경우 그냥 조상만 써주는 것과 똑같기 때문에 불필요한 코드가 발생해서 이다. 

또한, 멀티 `catch블럭`에 선언된 참조변수 `e`는 **상수이므로 값을 변경할 수 없다.**

## 6. 예외 발생시키기

키워드 `throw`를 사용해서 프로그래머가 고의로 예외를 발생시킬 수 있으며, 방법은 아래의 순서를 따르면 된다. 

```
1. 먼저, 연산자 `new`로 발생시키려는 예외 클래스의 객체를 생성
    
    `Exception e = new Exception(”고의로 발생시켰음”);`
    
2. 키워드 `throw`를 이용해서 예외를 발생시킨다. (예외를 던진다)
    
    `throw e;`
```

`Exception`인스턴스를 생성할 때, 생성자에 문자열을 넣어 주면, 이 문자열이 `Exception`인스턴스에 메시지로 저장된다. 이 메시지는 `getMessage()`를 이용해서 얻을 수 있다.

`Exception`클래스들은 예외 처리를 해주지 않으면 컴파일 에러가 발생한다. 

반면에 `RuntimeException`이 발생하면 컴파일은 성공적으로 되지만, 비정상적으로 프로그램이 종료된다. ⇒ 런타임 에러

(런타임 에러는 JVM이 찍어주고, 컴파일 에러는 컴파일러가 찍어준다!)

`RuntimeException`에 해당하는 예외는 프로그래머에 의해 실수로 발생하는 것들이기 때문에, 예외처리를 강제하지 않는다.

```
💡
컴파일러가 예외 처리를 확인하지 않는 RuntimeException클래스들은 ‘unchecked예외’라고 부르고, 예외 처리를 확인하는 Exception클래스들은 ‘checked예외’라고 부른다. 
```

## 7. 메서드에 예외 선언하기

예외를 메서드에 선언하는 방법이 있는데, 이는 실제로 예외를 처리하는 것이 아니라, 이 **메서드를 호출하는 쪽에서 예외를 처리하도록 알려주는 것**이다. 즉, 예외 처리를 호출한 쪽으로 떠넘기는 것이다.

```java
void method() **throws** Exception1, Exception2, ... ExceptionN {
  // 메서드의 내용
}
```

메서드의 선언부에 예외를 선언함으로써 메서드를 사용하려는 사람이 메서드의 선언부를 보았을 때, **이 메서드를 사용하기 위해서는 어떠한 예외들을 처리해야 하는지 쉽게 알 수 있다.** 

메서드에 예외를 선언할 때는 일반적으로 `RuntimeException클래스`들은 적지 않고, 보통 **반드시 처리해주어야 하는 필수 예외들만 선언한다.**

또한, 예외처리를 하지 않고 예외를 단순히 전달만 하는 것이기 때문에, 결국 어느 한 곳에서는 반드시 `try-catch문`으로 예외 처리를 해주어야 한다.

## 8. finally블럭

`finally블럭`은 예외의 발생여부에 상관없이 실행되어야하는 코드를 포함시킬 목적으로 사용된다. `try-catch-finally`의 순서로 구성된다.

```java
try {
  // 예외가 발생할 가능성이 있는 문장들
} catch (Exception1 e1) {
  // 예외처리를 위한 문장들
} finally {
  // 예외의 발생 여부에 관계없이 항상 수행되어야 하는 문장들
}
```

만약 `deleteTempFiles()`처럼 파일 복사 성공 여부에 관계없이 임시 파일이 삭제되도록 하고 싶다면 `finally블럭`에 사용하면 좋다. 

`try`안에 `return문`이 있는 경우에도 `finally블럭`의 문장들이 먼저 실행된 후에 `return` 시킨다. (그치만 return 뒤에 있는 문장들은 수행되지 않는다.) ⇒ **finally 무조건 실행**

## 9. 자동 자원 반환 - try-with-resources문

### **try-with-resources 문이란?**

Java 7부터 도입된 **자동 자원 관리 구문**으로, InputStream·Reader·Connection처럼 **반드시 close() 해 줘야 하는 객체**(= *resource*)를 try 괄호 안에 선언하면 **블록을 벗어날 때 자동으로 닫아준다.** 

덕분에 전통적인 `try-catch-finally`에서 `finally { resource.close(); }`를 직접 쓰지 않아도 **컴파일러가 대신 작성해준다**.

```java
try (BufferedReader br = Files.newBufferedReader(path)) {
    System.out.println(br.readLine());
}
```

컴파일 후엔 사실상 이렇게 변환됨 (컴파일러가 만들어 주는 코드)

```java
BufferedReader br = Files.newBufferedReader(path);
try {
    System.out.println(br.readLine());
} finally {
    if (br != null) br.close();
}
```

연결된 예외 장점

1. 예외를 더 큰 단위로 묶어처리 (단순화)
2. 필수예외를 선택 예외로 바꿔서 처리 가능 

## 10. 사용자 정의 예외 만들기

기존의 정의된 예외 클래스 외에 프로그래머가 새로운 예외 클래스를 직접 정의하여 사용할 수 있다. 보통 `Exception클래스` 또는 `RuntimeException클래스`로부터 상속받아 클래스를 만들지만, 필요에 따라서 알맞은 예외 클래스를 선택해도 된다.

만들때 제일 중요한건 필수로 할거냐 선택으로 할거냐. (필수는 사용자 실수, 선택은 개발자 실수)

```java
public class NegativeQuantityException extends RuntimeException {
    public NegativeQuantityException(int qty) {
        super("수량은 0 이상이어야 합니다. 전달된 값 = " + qty);
    }
}
```

사용

```java
public void addToCart(String sku, int qty) {
    if (qty < 0) throw new NegativeQuantityException(qty);
    ...
}
```

*잘못된 파라미터를 넘기는 건 **버그**이므로 호출자에게 강제하지 않고 즉시 런타임 예외로 터뜨린다.*
